Workbook
Name Slicer_Product_ID: #N/A

Sheet Products
A1: Product_ID | B1: Product_Name | C1: Product_Category | D1: Model_Name | E1: Unit_Price | F1: Standard_Production_Cost | G1: Reorder_Level | H1: Product_Status
A2: P001 | B2: Brizstar Farrata 20 | C2: Farrata Fan | D2: Brizstar 20 | E2: 3299 | F2: 2180 | G2: 60 | H2: Active
A3: P002 | B3: High Speed Personal Fan | C3: Personal Fan | D3: Personal 300 | E3: 1899 | F3: 1220 | G3: 80 | H3: Active
A4: P003 | B4: High Speed Wall Fan | C4: Wall Fan | D4: Wall 400 | E4: 2799 | F4: 1840 | G4: 70 | H4: Active
A5: P004 | B5: High Speed Table Fan | C5: Table Fan | D5: Table 400 | E5: 2599 | F5: 1690 | G5: 75 | H5: Active
A6: P005 | B6: High Speed Pedestal Fan | C6: Pedestal Fan | D6: Pedestal 400 | E6: 3499 | F6: 2310 | G6: 50 | H6: Active
A7: P006 | B7: Heavy Duty Exhaust Fan | C7: Exhaust Fan | D7: Exhaust 300 | E7: 2299 | F7: 1480 | G7: 65 | H7: Active
A8: P007 | B8: Air Flow Ventilation Fan | C8: Ventilation Fan | D8: Ventilation 250 | E8: 1999 | F8: 1270 | G8: 70 | H8: Active
A9: P008 | B9: Industrial Axial Fan | C9: Axial Fan | D9: Axial 450 | E9: 5499 | F9: 3710 | G9: 30 | H9: Active
A10: P009 | B10: Instant Water Geyser | C10: Geyser | D10: Instant 3L | E10: 4499 | F10: 3020 | G10: 40 | H10: Active
A11: P010 | B11: Storage Water Geyser | C11: Geyser | D11: Storage 15L | E11: 7499 | F11: 5140 | G11: 30 | H11: Active
A12: P011 | B12: Quartz Room Heater | C12: Heater | D12: Quartz 800 | E12: 2199 | F12: 1390 | G12: 60 | H12: Active
A13: P012 | B13: Heat Convector | C13: Heater | D13: Convector 2000 | E13: 3799 | F13: 2480 | G13: 45 | H13: Active

Sheet Raw_Materials
A1: Material_ID | B1: Material_Name | C1: Material_Category | D1: Unit_of_Measure | E1: Standard_Unit_Cost | F1: Reorder_Level | G1: Material_Status
A2: RM001 | B2: Fan Motor | C2: Electrical | D2: Pcs | E2: 650 | F2: 100 | G2: Active
A3: RM002 | B3: Fan Blade Set | C3: Plastic | D3: Pcs | E3: 180 | F3: 150 | G3: Active
A4: RM003 | B4: Fan Body Assembly | C4: Plastic | D4: Pcs | E4: 320 | F4: 100 | G4: Active
A5: RM004 | B5: Fan Guard Set | C5: Metal | D5: Pcs | E5: 240 | F5: 100 | G5: Active
A6: RM005 | B6: Pedestal Stand Assembly | C6: Metal | D6: Pcs | E6: 420 | F6: 60 | G6: Active
A7: RM006 | B7: Power Cord | C7: Electrical | D7: Pcs | E7: 85 | F7: 200 | G7: Active
A8: RM007 | B8: Speed Control Switch | C8: Electrical | D8: Pcs | E8: 110 | F8: 150 | G8: Active
A9: RM008 | B9: Capacitor | C9: Electrical | D9: Pcs | E9: 45 | F9: 300 | G9: Active
A10: RM009 | B10: Bearing | C10: Mechanical | D10: Pcs | E10: 70 | F10: 250 | G10: Active
A11: RM010 | B11: Copper Wire | C11: Electrical | D11: Kg | E11: 780 | F11: 50 | G11: Active
A12: RM011 | B12: Plastic Granules | C12: Plastic | D12: Kg | E12: 125 | F12: 200 | G12: Active
A13: RM012 | B13: Steel Sheet | C13: Metal | D13: Kg | E13: 95 | F13: 300 | G13: Active
... A26: RM025 | B26: Protective Packaging Material | C26: Packaging | D26: Pcs | E26: 32 | F26: 300 | G26: Active

Sheet Suppliers
A1: Supplier_ID | B1: Supplier_Name | C1: Supplier_Category | D1: City | E1: State | F1: Payment_Terms_Days | G1: Supplier_Status
A2: S001 | B2: JK Industries | C2: Electrical Components | D2: Bawana | E2: Delhi | F2: 30 | G2: Active
A3: S002 | B3: VK Enterprises | C3: Plastic Components | D3: Delhi | E3: Delhi | F3: 30 | G3: Active
A4: S003 | B4: MGV Exports Pvt Ltd | C4: Plastic Components | D4: Kundli | E4: Haryana | F4: 45 | G4: Active
A5: S004 | B5: Vizag Plastics | C5: Plastic Components | D5: Delhi | E5: Delhi | F5: 30 | G5: Active
A6: S005 | B6: Himani Industries | C6: Metal Components | D6: Delhi | E6: Delhi | F6: 30 | G6: Active
A7: S006 | B7: SAI Industries | C7: Metal Components | D7: Delhi | E7: Delhi | F7: 30 | G7: Active
A8: S007 | B8: OM Industries | C8: Metal Components | D8: Delhi | E8: Delhi | F8: 45 | G8: Active
A9: S008 | B9: RR Industries | C9: Metal Components | D9: Agra | E9: Uttar Pradesh | F9: 45 | G9: Active
A10: S009 | B10: Concord Industries | C10: Electrical Components | D10: Delhi | E10: Delhi | F10: 30 | G10: Active
A11: S010 | B11: Preeti Electricals | C11: Electrical Components | D11: Delhi | E11: Delhi | F11: 30 | G11: Active
A12: S011 | B12: Tuffcore Private Limited | C12: Electrical and Plastic Components | D12: Delhi | E12: Delhi | F12: 45 | G12: Active
A13: S012 | B13: Faridabad Sales Corporation | C13: Mechanical Components | D13: Faridabad | E13: Haryana | F13: 30 | G13: Active
... A29: S028 | B29: S Kumar Tubes | C29: Heating Components | D29: Bawana | E29: Delhi | F29: 30 | G29: Active

Sheet BOM
A1: BOM_ID | B1: Product_ID | C1: Material_ID | D1: Quantity_Required | E1: Wastage_Percent | F1: Effective_From | G1: BOM_Status
A2: BOM001 | B2: P001 | C2: RM001 | D2: 1 | E2: 2 | F2: 45658 | G2: Active
A3: BOM002 | B3: P001 | C3: RM002 | D3: 1 | E3: 1.5 | F3: 45658 | G3: Active
A4: BOM003 | B4: P001 | C4: RM003 | D4: 1 | E4: 2 | F4: 45658 | G4: Active
A5: BOM004 | B5: P001 | C5: RM004 | D5: 1 | E5: 1 | F5: 45658 | G5: Active
A6: BOM005 | B6: P001 | C6: RM006 | D6: 1 | E6: 1 | F6: 45658 | G6: Active
A7: BOM006 | B7: P001 | C7: RM007 | D7: 1 | E7: 1 | F7: 45658 | G7: Active
A8: BOM007 | B8: P001 | C8: RM008 | D8: 1 | E8: 2 | F8: 45658 | G8: Active
A9: BOM008 | B9: P001 | C9: RM009 | D9: 2 | E9: 1 | F9: 45658 | G9: Active
A10: BOM009 | B10: P001 | C10: RM022 | D10: 1 | E10: 2 | F10: 45658 | G10: Active
A11: BOM010 | B11: P001 | C11: RM023 | D11: 1 | E11: 1 | F11: 45658 | G11: Active
A12: BOM011 | B12: P001 | C12: RM024 | D12: 1 | E12: 0.5 | F12: 45658 | G12: Active
A13: BOM012 | B13: P001 | C13: RM025 | D13: 1 | E13: 1 | F13: 45658 | G13: Active
... A134: BOM133 | B134: P012 | C134: RM025 | D134: 1 | E134: 1 | F134: 45658 | G134: Active

Sheet Purchases
A1: Purchase_ID | B1: Purchase_Date | C1: Supplier_ID | D1: Material_ID | E1: Purchase_Quantity | F1: Unit_Cost | G1: Discount_Percent | H1: GST_Percent | I1: Delivery_Status | J1: Purchase_Value
A2: PUR0575 | B2: 45658 | C2: S006 | D2: RM005 | E2: 122 | F2: 429.99 | G2: 0 | H2: 18 | I2: Delivered | J2: =E2*F2*(1-G2/100)*(1+H2/100) -> 61901.36
A3: PUR0463 | B3: 45658 | C3: S005 | D3: RM014 | E3: 232 | F3: 1439.59 | G3: 3 | H3: 18 | I3: Delivered | J3: =E3*F3*(1-G3/100)*(1+H3/100) -> 382279.09
A4: PUR0637 | B4: 45658 | C4: S017 | D4: RM020 | E4: 80 | F4: 370.94 | G4: 0 | H4: 18 | I4: Delivered | J4: =E4*F4*(1-G4/100)*(1+H4/100) -> 35016.736
A5: PUR0639 | B5: 45658 | C5: S016 | D5: RM005 | E5: 439 | F5: 432.72 | G5: 3 | H5: 18 | I5: Delivered | J5: =E5*F5*(1-G5/100)*(1+H5/100) -> 217432.89
A6: PUR0070 | B6: 45659 | C6: S027 | D6: RM025 | E6: 389 | F6: 33.58 | G6: 2 | H6: 12 | I6: Partial | J6: =E6*F6*(1-G6/100)*(1+H6/100) -> 14337.532
A7: PUR0112 | B7: 45659 | C7: S004 | D7: RM021 | E7: 666 | F7: 34.31 | G7: 5 | H7: 18 | I7: Delivered | J7: =E7*F7*(1-G7/100)*(1+H7/100) -> 25615.366
A8: PUR0118 | B8: 45659 | C8: S025 | D8: RM024 | E8: 174 | F8: 18.22 | G8: 0 | H8: 12 | I8: Delivered | J8: =E8*F8*(1-G8/100)*(1+H8/100) -> 3550.7136
A9: PUR0437 | B9: 45661 | C9: S011 | D9: RM011 | E9: 144 | F9: 127.92 | G9: 0 | H9: 18 | I9: Delivered | J9: =E9*F9*(1-G9/100)*(1+H9/100) -> 21736.166
A10: PUR0595 | B10: 45663 | C10: S008 | D10: RM012 | E10: 115 | F10: 89.87 | G10: 5 | H10: 18 | I10: Delivered | J10: =E10*F10*(1-G10/100)*(1+H10/100) -> 11585.591
A11: PUR0650 | B11: 45663 | C11: S003 | D11: RM021 | E11: 418 | F11: 33.8 | G11: 5 | H11: 18 | I11: Delayed | J11: =E11*F11*(1-G11/100)*(1+H11/100) -> 15837.936
A12: PUR0191 | B12: 45665 | C12: S019 | D12: RM014 | E12: 541 | F12: 1429.29 | G12: 5 | H12: 18 | I12: Delayed | J12: =E12*F12*(1-G12/100)*(1+H12/100) -> 866808.64
A13: PUR0694 | B13: 45665 | C13: S005 | D13: RM005 | E13: 286 | F13: 404.06 | G13: 5 | H13: 18 | I13: Delayed | J13: =E13*F13*(1-G13/100)*(1+H13/100) -> 129544.06
... A701: PUR0622 | B701: 46022 | C701: S012 | D701: RM016 | E701: 240 | F701: 175.54 | G701: 0 | H701: 18 | I701: Delivered | J701: =E701*F701*(1-G701/100)*(1+H701/100) -> 49712.928

Sheet Production
A1: Production_ID | B1: Production_Date | C1: Product_ID | D1: Planned_Quantity | E1: Produced_Quantity | F1: Rejected_Quantity | G1: Shift | H1: Production_Line
A2: PRD0059 | B2: 45658 | C2: P005 | D2: 447 | E2: 424 | F2: 15 | G2: Evening | H2: Line 2
A3: PRD0490 | B3: 45658 | C3: P003 | D3: 175 | E3: 167 | F3: 4 | G3: Night | H3: Line 2
A4: PRD0136 | B4: 45658 | C4: P005 | D4: 364 | E4: 332 | F4: 12 | G4: Night | H4: Line 2
A5: PRD0100 | B5: 45658 | C5: P004 | D5: 257 | E5: 240 | F5: 8 | G5: Evening | H5: Line 1
A6: PRD0199 | B6: 45659 | C6: P004 | D6: 472 | E6: 433 | F6: 11 | G6: Night | H6: Line 1
A7: PRD0024 | B7: 45659 | C7: P004 | D7: 212 | E7: 196 | F7: 6 | G7: Morning | H7: Line 1
A8: PRD0352 | B8: 45660 | C8: P011 | D8: 386 | E8: 370 | F8: 5 | G8: Night | H8: Line 5
A9: PRD0361 | B9: 45661 | C9: P002 | D9: 232 | E9: 219 | F9: 8 | G9: Morning | H9: Line 1
A10: PRD0118 | B10: 45663 | C10: P007 | D10: 430 | E10: 397 | F10: 9 | G10: Morning | H10: Line 1
A11: PRD0022 | B11: 45663 | C11: P007 | D11: 203 | E11: 185 | F11: 7 | G11: Night | H11: Line 1
A12: PRD0082 | B12: 45664 | C12: P001 | D12: 488 | E12: 449 | F12: 10 | G12: Morning | H12: Line 1
A13: PRD0384 | B13: 45665 | C13: P007 | D13: 185 | E13: 178 | F13: 3 | G13: Evening | H13: Line 1
... A501: PRD0433 | B501: 46022 | C501: P012 | D501: 209 | E501: 204 | F501: 4 | G501: Evening | H501: Line 5

Sheet Inventory
A1: Inventory_Transaction_ID | B1: Transaction_Date | C1: Material_ID | D1: Transaction_Type | E1: Quantity | F1: Warehouse | G1: Reference_ID
A2: INV00001 | B2: 45658 | C2: RM001 | D2: Opening Stock | E2: 107702.23 | F2: Raw Material Warehouse | G2: OPEN-RM001
A3: INV00002 | B3: 45658 | C3: RM002 | D3: Opening Stock | E3: 104399.24 | F3: Raw Material Warehouse | G3: OPEN-RM002
A4: INV00003 | B4: 45658 | C4: RM003 | D4: Opening Stock | E4: 92577.44 | F4: Raw Material Warehouse | G4: OPEN-RM003
A5: INV00004 | B5: 45658 | C5: RM004 | D5: Opening Stock | E5: 70351.84 | F5: Raw Material Warehouse | G5: OPEN-RM004
A6: INV00005 | B6: 45658 | C6: RM005 | D6: Opening Stock | E6: 13736.33 | F6: Raw Material Warehouse | G6: OPEN-RM005
A7: INV00006 | B7: 45658 | C7: RM006 | D7: Opening Stock | E7: 157964.33 | F7: Raw Material Warehouse | G7: OPEN-RM006
A8: INV00007 | B8: 45658 | C8: RM007 | D8: Opening Stock | E8: 71100.84 | F8: Raw Material Warehouse | G8: OPEN-RM007
A9: INV00008 | B9: 45658 | C9: RM008 | D9: Opening Stock | E9: 106972.23 | F9: Raw Material Warehouse | G9: OPEN-RM008
A10: INV00009 | B10: 45658 | C10: RM009 | D10: Opening Stock | E10: 214598.08 | F10: Raw Material Warehouse | G10: OPEN-RM009
A11: INV00010 | B11: 45658 | C11: RM010 | D11: Opening Stock | E11: 501.92 | F11: Raw Material Warehouse | G11: OPEN-RM010
A12: INV00011 | B12: 45658 | C12: RM011 | D12: Opening Stock | E12: 200 | F12: Raw Material Warehouse | G12: OPEN-RM011
A13: INV00012 | B13: 45658 | C13: RM012 | D13: Opening Stock | E13: 6216.71 | F13: Raw Material Warehouse | G13: OPEN-RM012
... A6230: INV06229 | B6230: 46022 | C6230: RM016 | D6230: Purchase Receipt | E6230: 240 | F6230: Raw Material Warehouse | G6230: PUR0622

Sheet Purchase_Analysis
A1: Purchase Analysis
O2: Row Labels | P2: Sum of Purchase_Quantity
A3: Total Purchase Transactions | B3: =COUNTA(tblPurchases[Purchase_ID]) -> 700 | D3: Delivery Status | E3: Transaction Count | O3: S013 | P3: 10186
A4: Total Purchase Quantity | B4: =SUM(tblPurchases[Purchase_Quantity]) -> 196193 | D4: Delivered | E4: =COUNTIF(tblPurchases[Delivery_Status],D4) -> 579 | O4: S022 | P4: 9693
A5: Total Purchase Value | B5: =SUM(tblPurchases[Purchase_Value]) -> 67241528 | D5: Delayed | E5: =COUNTIF(tblPurchases[Delivery_Status],D5) -> 86 | O5: S015 | P5: 9594
A6: Average Purchase Quantity | B6: =AVERAGE(tblPurchases[Purchase_Quantity]) -> 280.27571 | D6: Partial | E6: =COUNTIF(tblPurchases[Delivery_Status],D6) -> 35 | O6: S008 | P6: 9198
A7: Average Unit Cost | B7: =AVERAGE(tblPurchases[Unit_Cost]) -> 299.01117 | O7: S006 | P7: 9061
A8: Average Discount % | B8: =AVERAGE(tblPurchases[Discount_Percent]) -> 3.0928571 | O8: S002 | P8: 8267
A9: Delivered Transactions | B9: =COUNTIF(tblPurchases[Delivery_Status],"Delivered") -> 579 | O9: S014 | P9: 8239
A10: Delayed Transactions | B10: =COUNTIF(tblPurchases[Delivery_Status],"Delayed") -> 86 | O10: S024 | P10: 8007
A11: Partial Transactions | B11: =COUNTIF(tblPurchases[Delivery_Status],"Partial") -> 35 | O11: S018 | P11: 7826
A12: Delivery Rate % | B12: =B9/B3 -> 0.82714286 | O12: S028 | P12: 7754
A13: Delay Rate % | B13: =B10/B3 -> 0.12285714 | O13: S019 | P13: 7566
A14: Partial Delivery Rate % | B14: =B11/B3 -> 0.05 | O14: S007 | P14: 7343
O15: S016 | P15: 7340
O16: S005 | P16: 7313
O17: S004 | P17: 7252
A18: Row Labels | B18: Sum of Purchase_Quantity | O18: S021 | P18: 7196
A19: 2025 | B19: 196193 | O19: S026 | P19: 6536
A20: Jan | B20: 13174 | O20: S027 | P20: 6328
A21: Feb | B21: 20315 | O21: S011 | P21: 6322
A22: Mar | B22: 16135 | O22: S003 | P22: 5947
A23: Apr | B23: 11482 | O23: S025 | P23: 5917
A24: Mei | B24: 16025 | O24: S017 | P24: 5614
A25: Jun | B25: 17445 | O25: S023 | P25: 5539
A26: Jul | B26: 20457 | O26: S020 | P26: 4762
A27: Agu | B27: 16384 | O27: S012 | P27: 4672
A28: Sep | B28: 17712 | O28: S009 | P28: 4646
A29: Okt | B29: 14406 | O29: S001 | P29: 4570
A30: Nov | B30: 14578 | O30: S010 | P30: 3505
A31: Des | B31: 18080
O35: Row Labels | P35: Sum of Purchase_Quantity
O36: RM019 | P36: 15322
O37: RM023 | P37: 11998
O38: RM011 | P38: 11631
O39: RM014 | P39: 10636
O40: RM013 | P40: 10501
O41: RM012 | P41: 10465
O42: RM015 | P42: 9921
O43: RM024 | P43: 9697
...

Sheet Production_Analysis
A1: Production Analysis Dashboard
B3: Total Planned Qty | D3: Total Produced Qty | F3: Total Rejected Qty | H3: Rejection % | J3: Total Production Orders | L3: Average Produced Qty
B4: =SUM(Production!D:D) -> 145921 | D4: =SUM(Production!E:E) -> 138937 | F4: =SUM(Production!F:F) -> 2800 | H4: =F4/D4 -> 0.020153019 | J4: =COUNTA(Production!A:A)-1 -> 500 | L4: =AVERAGE(Production!E:E) -> 277.874
B9: Row Labels | C9: Sum of Produced_Quantity | H9: Row Labels | I9: Sum of Produced_Quantity
B10: Jan | C10: 3353 | H10: P001 | I10: 9461
B11: Feb | C11: 1671 | H11: P002 | I11: 13715
B12: Mar | C12: 2295 | H12: P003 | I12: 14629
B13: Apr | C13: 4767 | H13: Grand Total | I13: 37805
B14: Mei | C14: 2151
B15: Jun | C15: 5476
B16: Jul | C16: 3463
B17: Agu | C17: 3174
B18: Sep | C18: 2191
B19: Okt | C19: 2914
B20: Nov | C20: 2829
B21: Des | C21: 3521
B22: Grand Total | C22: 37805
A25: Row Labels | B25: Sum of Produced_Quantity | H25: Row Labels | I25: Sum of Produced_Quantity
A26: Evening | B26: 14123 | H26: Line 1 | I26: 23176
A27: Morning | B27: 16303 | H27: Line 2 | I27: 14629
A28: Night | B28: 7379 | H28: Grand Total | I28: 37805
A29: Grand Total | B29: 37805
A41: Row Labels | B41: Sum of Rejected_Quantity | G41: Row Labels | H41: Sum of Planned_Quantity | I41: Sum of Produced_Quantity
A42: P001 | B42: 198 | G42: P001 | H42: 9966 | I42: 9461
A43: P002 | B43: 258 | G43: P002 | H43: 14425 | I43: 13715
A44: P003 | B44: 297 | G44: P003 | H44: 15347 | I44: 14629
A45: Grand Total | B45: 753 | G45: Grand Total | H45: 39738 | I45: 37805

Sheet Helper
